now processing task id: 4
CORPUS: UD_Chinese-CFL
python preprocess_treebank.py UD_Chinese-CFL --experiment-name inter-layer-13 --treebanks-root /home/s2308470/multilingual-typology-probing/data/ud/ud-treebanks-v2.1 --bloom bloom-1b1 --checkpoint 200000 --inter-layer 13 --use-gpu
Embeddings root: embeddings
Using GPU
0it [00:00, ?it/s]55it [00:00, 522.35it/s]132it [00:00, 661.17it/s]199it [00:00, 635.65it/s]263it [00:00, 610.21it/s]325it [00:00, 532.11it/s]380it [00:00, 501.61it/s]432it [00:00, 473.53it/s]451it [00:00, 523.89it/s]
Skipped:
{'total_sents': 451}

Total: 0
Using model bloom-1b1-intermediate-global_step200000...
Processing UD_Chinese-CFL...
Traceback (most recent call last):
  File "/home/s2308470/miniconda3/envs/multilingual-typology-probing/lib/python3.8/site-packages/urllib3/connection.py", line 174, in _new_conn
    conn = connection.create_connection(
  File "/home/s2308470/miniconda3/envs/multilingual-typology-probing/lib/python3.8/site-packages/urllib3/util/connection.py", line 95, in create_connection
    raise err
  File "/home/s2308470/miniconda3/envs/multilingual-typology-probing/lib/python3.8/site-packages/urllib3/util/connection.py", line 85, in create_connection
    sock.connect(sa)
OSError: [Errno 101] Network is unreachable

During handling of the above exception, another exception occurred:

Traceback (most recent call last):
  File "/home/s2308470/miniconda3/envs/multilingual-typology-probing/lib/python3.8/site-packages/urllib3/connectionpool.py", line 703, in urlopen
    httplib_response = self._make_request(
  File "/home/s2308470/miniconda3/envs/multilingual-typology-probing/lib/python3.8/site-packages/urllib3/connectionpool.py", line 386, in _make_request
    self._validate_conn(conn)
  File "/home/s2308470/miniconda3/envs/multilingual-typology-probing/lib/python3.8/site-packages/urllib3/connectionpool.py", line 1042, in _validate_conn
    conn.connect()
  File "/home/s2308470/miniconda3/envs/multilingual-typology-probing/lib/python3.8/site-packages/urllib3/connection.py", line 363, in connect
    self.sock = conn = self._new_conn()
  File "/home/s2308470/miniconda3/envs/multilingual-typology-probing/lib/python3.8/site-packages/urllib3/connection.py", line 186, in _new_conn
    raise NewConnectionError(
urllib3.exceptions.NewConnectionError: <urllib3.connection.HTTPSConnection object at 0x7f445640d490>: Failed to establish a new connection: [Errno 101] Network is unreachable

During handling of the above exception, another exception occurred:

Traceback (most recent call last):
  File "/home/s2308470/miniconda3/envs/multilingual-typology-probing/lib/python3.8/site-packages/requests/adapters.py", line 486, in send
    resp = conn.urlopen(
  File "/home/s2308470/miniconda3/envs/multilingual-typology-probing/lib/python3.8/site-packages/urllib3/connectionpool.py", line 787, in urlopen
    retries = retries.increment(
  File "/home/s2308470/miniconda3/envs/multilingual-typology-probing/lib/python3.8/site-packages/urllib3/util/retry.py", line 592, in increment
    raise MaxRetryError(_pool, url, error or ResponseError(cause))
urllib3.exceptions.MaxRetryError: HTTPSConnectionPool(host='huggingface.co', port=443): Max retries exceeded with url: /bigscience/bloom-1b1-intermediate/resolve/global_step200000/tf_model.h5 (Caused by NewConnectionError('<urllib3.connection.HTTPSConnection object at 0x7f445640d490>: Failed to establish a new connection: [Errno 101] Network is unreachable'))

During handling of the above exception, another exception occurred:

Traceback (most recent call last):
  File "preprocess_treebank.py", line 374, in <module>
    model = BloomModel.from_pretrained(bloom_model, 
  File "/home/s2308470/miniconda3/envs/multilingual-typology-probing/lib/python3.8/site-packages/transformers/modeling_utils.py", line 2472, in from_pretrained
    if has_file(pretrained_model_name_or_path, TF2_WEIGHTS_NAME, **has_file_kwargs):
  File "/home/s2308470/miniconda3/envs/multilingual-typology-probing/lib/python3.8/site-packages/transformers/utils/hub.py", line 610, in has_file
    r = requests.head(url, headers=headers, allow_redirects=False, proxies=proxies, timeout=10)
  File "/home/s2308470/miniconda3/envs/multilingual-typology-probing/lib/python3.8/site-packages/requests/api.py", line 100, in head
    return request("head", url, **kwargs)
  File "/home/s2308470/miniconda3/envs/multilingual-typology-probing/lib/python3.8/site-packages/requests/api.py", line 59, in request
    return session.request(method=method, url=url, **kwargs)
  File "/home/s2308470/miniconda3/envs/multilingual-typology-probing/lib/python3.8/site-packages/requests/sessions.py", line 589, in request
    resp = self.send(prep, **send_kwargs)
  File "/home/s2308470/miniconda3/envs/multilingual-typology-probing/lib/python3.8/site-packages/requests/sessions.py", line 703, in send
    r = adapter.send(request, **kwargs)
  File "/home/s2308470/miniconda3/envs/multilingual-typology-probing/lib/python3.8/site-packages/requests/adapters.py", line 519, in send
    raise ConnectionError(e, request=request)
requests.exceptions.ConnectionError: HTTPSConnectionPool(host='huggingface.co', port=443): Max retries exceeded with url: /bigscience/bloom-1b1-intermediate/resolve/global_step200000/tf_model.h5 (Caused by NewConnectionError('<urllib3.connection.HTTPSConnection object at 0x7f445640d490>: Failed to establish a new connection: [Errno 101] Network is unreachable'))
